Workbook

Sheet Akseptasi
B2: Nama | C2: SITI HAFSAH
B3: Tanggal Lahir | C3: 28057 | E3: =DATEDIF(C3,C21,"Y")&"Tahun "&DATEDIF(C3,C21,"YM")&"bulan "&DATEDIF(C3,C21,"MD")&"hari" -> 50Tahun 0bulan 4hari
B4: NIP | C4: 1968012220071012004
B5: Gaji Pokok | C5: 4254800 | D5: 1 | E5: =C5*D5 -> 4254800
B6: Uang Makan | C6: 550000 | D6: 0.9 | E6: =C6*D6 -> 495000
B7: Tunjangan Rutin per 1 Bulan | C7: 3761240 | D7: 0.9 | E7: =C7*D7 -> 3385116
B8: Tunjangan Rutin per 3 Bulan | C8: 0 | D8: 0.5 | E8: =C8*D8 -> 0
B9: Tunjangan Lain Rutin per 1 Bulan | C9: 0 | D9: 0.8 | E9: =C9*D9 -> 0
E10: =SUM(E5:E9) -> 8134916 | F10: 0.7 | G10: =E10*F10 -> 5694441.2
B12: TMT Bekerja | C12: 39083
B13: TMT Pensiun (BUP) | C13: 2036
B14: THT | C14: 78600000 | F14: 0.75 | G14: =C14*F14 -> 58950000
B15: Pensiun | C15: 4600000 | F15: 0.9 | G15: =C15*F15 -> 4140000
B17: Tenor (Bulan): | C17: 180 | I17: Tri Nett 200 | J17: Dekade Nett 200 | K17: dibawah 200
B18: Price Saat Aktif: | C18: 0.0925 | E18: Sesuaikan Pricing yang Berlaku | H18: Rate Masa Aktif | I18: 9.25% | J18: 9.50% | K18: 10.50%
B19: Price Saat Pensiun: | C19: 0.105 | E19: Sesuaikan Pricing yang Berlaku | H19: Rate Masa Pensiun | I19: 10.50% | J19: 10.50% | K19: 11.50%
B21: Proyeksi Cair | C21: =NOW()+7 -> 46323.502
B22: Start Angsuran | C22: 46327
B23: Selesai Angsuran | C23: =EDATE(C22,C17-1) -> 51775 | E23: =DATEDIF(C3,C23,"Y")&"Tahun "&DATEDIF(C3,C23,"YM")&"bulan "&DATEDIF(C3,C23,"MD")&"hari" -> 64Tahun 11bulan 7hari | G23: (Setting Usia Jatuh Tempo Maks 74 Thn 4 bln x hari)
B25: Biaya Asuransi | C25: 39998267 | E25: Isi Dari Hasil Kalkulator Asuransi
B27: Buka Blokir Yang Lama | C27: 0
B28: Pelunasan Yang Lama | C28: =C65 -> 0
B30: Plafond Pra Pensiun | C30: =Simulasi!B10 -> 480000000
B31: Estimasi Taksasi MMQ | C31: =(2%*C30)+C30 -> 489600000 | E31: =ROUNDUP(C31,-6) -> 490000000
B40: Fasilitas Eksisting (Dilunasi/Tidak Dilunasi)
B41: Nama | C41: =C2 -> SITI HAFSAH
B42: Produk | C42: Mitraguna
B43: Akad Pembiayaan | C43: Murabahah
B44: Jenis Pelunasan | C44: Pelunasan di Percepat (Top Up Lunas Maju)
B45: Margin Dibayar | C45: n + 1 + Sisa Atribusi
B47: No. Loan | C47: LD2400931674 | E47: LD2206703248
B48: CIF | C48: 92236837 | E48: 80844000
B49: No. Rek Debet | C49: 7256353231 | E49: 7104565675
B50: Tanggal Cair | C50: 45300 | E50: 44628
B51: Tanggal Jatuh Tempo | C51: 47423 | E51: 48639
B52: Jangka Waktu Pembiayaan | C52: 70 | E52: 132
B53: Jangka Waktu Telah Dijalani | C53: 28
B54: Tunggakan | C54: 0
B55: Plafond Awal
B56: OS Pokok Pembiayaan
...

Sheet Simulasi
A1: SIMULASI NOS MITRAGUNA PRIMA+
A2: INPUT | D2: HIDE S.D Kol. W
A3: Tipe Produk: | B3: Prapen 10 Tahun | C3: =MID(B3,8,1) -> 1 | G3: AKTIF | H3: angsuran set | I3: cek angsuran maks akhir
A4: Status Payroll: | B4: Payroll | C4: =MID(B4,1,1) -> P | F4: P | G4: =MIN((B16-B19)*C16,0.7*(B16-B19)) -> 5694441.2 | H4: =B18-B19 -> 0 | I4: =IF($B$18=0,G4,MIN(G4,H4)) -> 5694441.2
A5: Tgl Proyeksi cair: | B5: =NOW()+7 -> 46323.502 | F5: C | G5: =MIN((B16-B19-B20)*C16,0.8*(B16-B19-B20)) -> 5694441.2 | H5: =B18-B19-B20 -> 0 | I5: =IF($B$18=0,G5,MIN(G5,H5)) -> 5694441.2
A6: Tgl Lahir: | B6: =Akseptasi!C3 -> 28057 | F6: N | G6: =MIN((B16-B19-B20)*C16,0.5*(B16-B19-B20)) -> 4067458 | H6: =B18-B19-B20 -> 0 | I6: =IF($B$18=0,G6,MIN(G6,H6)) -> 4067458
A7: TMT Bekerja: | B7: =Akseptasi!C12 -> 39083 | C7: =DATE(B8,MONTH(B6)+1,1) -> 49980 | F7: Pensiun Angs | G7: =B17*C17 -> 4140000 | H7: =G7 -> 4140000 | I7: =IF($B$18=0,G7,MIN(G7,H7)) -> 4140000
A8: Tahun BUP: | B8: =Akseptasi!C13 -> 2036 | C8: =ROUND((C7-B5)/30.5,0) -> 120 | D8: masa aktif
A9: Tanggal BUP: | B9: =C7 -> 49980 | C9: =C8/12 -> 10 | G9: 0.7
A10: Plafond Pengajuan: | B10: 480000000 | G10: 0.8
A11: Tenor (Bulan): | B11: =Akseptasi!C17 -> 180 | D11: =8*12 -> 96 | G11: 0.5
A12: Price Saat Aktif: | B12: =Akseptasi!C18 -> 0.0925 | D12: 7 | F12: 1. No Atribusi
A13: Price Saat Pensiun: | B13: =Akseptasi!C19 -> 0.105 | D13: =D11+D12 -> 103 | F13: 2. Atribusi Asuransi
A14: Tipe Atribusi: | B14: 2. Atribusi Asuransi | C14: =LEFT(B14,1) -> 2 | F14: 3. Atribusi Asuransi + Pinalti
A15: Tgl Pensiun: | B15: Murabahah
A16: Gaji Saat Ini (70%): | B16: =Akseptasi!E10 -> 8134916 | C16: =MID(A16,16,3) -> 70%
A17: Manfaat pensiun (90%) | B17: =Akseptasi!C15 -> 4600000 | C17: =MID(A17,18,3) -> 90% | X17: Minimal Angs Aktif
A18: =IF(C3="3","Wajib diisi 0","Set Angsuran Maks Aktif(Khusus Prapen 10 Tahun)") -> Set Angsuran Maks Aktif(Khusus Prapen 10 Tahun) | B18: 0 | X18: =IF(B18=0,0,$B$34/12*$B$31) -> 0
A19: Angsuran BSI: | B19: 0
A20: Angsuran Selain BSI: | B20: 0
A21: Biaya Asuransi: | B21: =Akseptasi!C25 -> 39998267
A22: Rate asuransi | B22: =15000000/(100000000+15000000) -> 0.13043478
A23: Biaya Pinalti: | B23: 0
A29: OUTPUT | E29: 1 | F29: 3
A30: Maksimal Plafon: | B30: =IF(IF($C$3="1",E30,F30)>800000000,800000000,IF($C$3="1",E30,F30)) -> 495000000 | D30: plaf mak | E30: ='Rumus Plafond + Atrib PP10 (2)'!C18 -> 495000000 | F30: =IF(C14="1",'Rumus Plafond + Atrib PP3'!C20,'Rumus Plafond + Atrib PP3'!C36) -> 178000000
A31: Plafond disetujui: | B31: =IF($C$3="1",E31,F31) -> 480000000 | D31: plaf mak atrb | E31: ='Rumus Plafond + Atrib PP10 (2)'!P3 -> 480000000 | F31: ='Rumus Plafond + Atrib PP3'!P3 -> 178000000
A32: ="Angs. Saat Aktif: DSR "&TEXT(C32,"00,0%") -> Angs. Saat Aktif: DSR 70,0% | B32: =IF($C$3="1",E32,F32) -> 5694441 | C32: =IFERROR((B32+B19)/B16,"") -> 0.69999998 | E32: ='Rumus Plafond + Atrib PP10 (2)'!C6 -> 5694441 | F32: ='Rumus Plafond + Atrib PP3'!V7 -> 1604295.9
A33: =IF(C33>0.9,"DSR>90%, ubah angs aktif/tenor","Angs. Saat Pensiun: DSR "&TEXT(C33,"00,0%")) -> Angs. Saat Pensiun: DSR 89,6% | B33: =IF(IF($C$3="1",E33,F33)<0,"LUNAS <PENSIUN",IF($C$3="1",E33,F33)) -> 4121876.7 | C33: =IFERROR(B33/B17,"") -> 0.89606016 | E33: ='Rumus Plafond + Atrib PP10 (2)'!V15 -> 4121876.7 | F33: ='Rumus Plafond + Atrib PP3'!V17 -> 4092900
A34: Price Atrib Pra Pensiun: | B34: =IF($C$3="1",E34,F34) -> 0.10805531 | E34: ='Rumus Plafond + Atrib PP10 (2)'!V5 -> 0.10805531 | F34: ='Rumus Plafond + Atrib PP3'!V6 -> 0.10748062
A35: Price Atrib Pasca Pensiun: | B35: =IF($C$3="1",E35,F35) -> 0.11936993 | E35: ='Rumus Plafond + Atrib PP10 (2)'!V14 -> 0.11936993 | F35: ='Rumus Plafond + Atrib PP3'!V16 -> 0.1401
A36: Biaya Atribusi Nasabah: | B36: =IF(C14="1",0,B21+B23) -> 39998267 | D36: plaf mak atrb2 | E36: ='Rumus Plafond + Atrib PP10 (2)'!C50 -> 455000000
A37: Nominal Blokir PPTB | B37: =IF(C3="3",(C8*B32)+2*B33,"blokir sesuai MP") -> blokir sesuai MP
A38: Cash on hand PPTB | B38: =IFERROR(B31-B37,"khusus PPTB") -> khusus PPTB
A39: Simulasi Pembiayaan lain (mitraguna, griya, dll)
A40: Maksimal Plafon: | B40: {=-PV(B12/12,C8,IF(B18=0,B16*_xlfn.IFS(C4="P",70%,C4="C",80%,C4="N",50%),B18))} -> 4.4476452e+08
A41: Angsuran mitraguna | B41: =-PMT(B12/12,C8,B31) -> 6145570.7
A42: Sisa masa aktif | B42: =C8 -> 120

Sheet Rumus Plafond + Atrib PP10 (2)
B1: DATA DIKETAHUI PP10th-Non Payroll | G1: Atrib & Non-Atrib | H1: fx=C18-I3 | I1: fx=K3-J3 | J1: fx=$C$25/12*C18 | K1: fx=$C$6 | O1: Jika plafon lebih besar, maka bisa digunakan untuk menghitung angsuran | AG1: cek EPR | AH1: 0.086947336
B2: Gaji Aktif | C2: =Simulasi!B16 -> 8134916 | G2: tenor ke- | H2: pokok/plafon disetujui | I2: angsuran pokok | J2: angsuran margin | K2: total angsuran | O2: tenor ke- | P2: pokok/plafon disetujui | Q2: angsuran pokok | R2: angsuran margin | S2: total angsuran | U2: Kalkulasi Angsuran Aktif | AB2: 180 | AG2: rate net | AH2: atribusi | AI2: pokok+atrib | AJ2: atrib | AK2: margin net | AL2: Y on Pokok
B3: Manf Pens | C3: =Simulasi!B17 -> 4600000 | G3: 0 | H3: =C18 -> 495000000 | O3: 0 | P3: =IF(Simulasi!C14="1",MIN('Rumus Plafond + Atrib PP10 (2)'!C14,'Rumus Plafond + Atrib PP10 (2)'!C18),MIN('Rumus Plafond + Atrib PP10 (2)'!C14,'Rumus Plafond + Atrib PP10 (2)'!C45)) -> 480000000 | U3: Margin | V3: =P3*Simulasi!$B$12/12 -> 3700000 | Z3: 7000000 | AA3: 0.105 | AB3: 48 | AC3: =ROUNDDOWN(-PV(AA3/12,AB3,Z3,AC4,0)/10^6,0)*10^6 -> 450000000 | AH3: =SUM(AH4:AH183) -> 1.1166916e+08 | AI3: =P3+AJ3 -> 519998267 | AJ3: =$C$13 -> 39998267
B4: DBR Aktif | C4: =Simulasi!C16 -> 70% | G4: 1 | H4: =H3-I4 -> 493385184 | I4: =K4-J4 -> 1614816 | J4: =IF(G4<=$C$9,H3*$C$25/12,H3*$C$35/12) -> 4079625 | K4: =IFERROR(IF(G4<=$C$8,IF(G4<=$C$9,$C$6,$C$36),0),0) -> 5694441 | O4: 1 | P4: =P3-Q4 -> 4.7862777e+08 | Q4: =S4-R4 -> 1372228.4 | R4: =IF(O4<=$C$9,P3*$V$5/12,P3*$V$14/12) -> 4322212.6 | S4: =IFERROR(IF(O4<=$C$8,IF(O4<=$C$9,$C$6,$V$15),0),0) -> 5694441 | U4: Atrib per bln | V4: =D13 -> 222212.59 | Z4: 3590602.7 | AA4: 0.115 | AB4: =AB2-AB3 -> 132 | AC4: =-PV(AA4/12,AB4,Z4,0,0) -> 2.6828571e+08 | AF4: 1 | AG4: =$AH$1/12*AI3 -> 3767705.3 | AH4: =R4-AG4 -> 554507.25 | AI4: =AI3-Q4-AH4 -> 5.1807153e+08 | AJ4: =AJ3-AH4 -> 39443760
B5: DSR Pensiun | C5: =Simulasi!C17 -> 90% | G5: 2 | H5: =H4-I5 -> 4.9175706e+08 | I5: =K5-J5 -> 1628124.8 | J5: =IF(G5<=$C$9,H4*$C$25/12,H4*$C$35/12) -> 4066316.2 | K5: =IFERROR(IF(G5<=$C$8,IF(G5<=$C$9,$C$6,$C$36),0),0) -> 5694441 | O5: 2 | P5: =P4-Q5 -> 4.7724319e+08 | Q5: =S5-R5 -> 1384584.8 | R5: =IF(O5<=$C$9,P4*$V$5/12,P4*$V$14/12) -> 4309856.2 | S5: =IFERROR(IF(O5<=$C$8,IF(O5<=$C$9,$C$6,$V$15),0),0) -> 5694441 | U5: Rate | V5: =(V3+V4)/P3*12+IF($D$13>0,0.01,0) -> 0.10805531 | AF5: 2 | AG5: =$AH$1/12*AI4 -> 3753745 | AH5: =R5-AG5 -> 556111.24 | AI5: =AI4-Q5-AH5 -> 5.1613084e+08 | AJ5: =AJ4-AH5 -> 38887649
B6: Akseptasi Aktif | C6: =ROUNDDOWN(VLOOKUP(Simulasi!C4,Simulasi!$F$4:$I$6,4,FALSE), ) -> 5694441 | D6: fx=C2*C4 | G6: 3 | H6: =H5-I6 -> 4.9011552e+08 | I6: =K6-J6 -> 1641543.2 | J6: =IF(G6<=$C$9,H5*$C$25/12,H5*$C$35/12) -> 4052897.8 | K6: =IFERROR(IF(G6<=$C$8,IF(G6<=$C$9,$C$6,$C$36),0),0) -> 5694441 | O6: 3 | P6: =P5-Q6 -> 4.7584613e+08 | Q6: =S6-R6 -> 1397052.4 | R6: =IF(O6<=$C$9,P5*$V$5/12,P5*$V$14/12) -> 4297388.6 | S6: =IFERROR(IF(O6<=$C$8,IF(O6<=$C$9,$C$6,$V$15),0),0) -> 5694441 | AF6: 3 | AG6: =$AH$1/12*AI5 -> 3739683.4 | AH6: =R6-AG6 -> 557705.13 | AI6: =AI5-Q6-AH6 -> 5.1417608e+08 | AJ6: =AJ5-AH6 -> 38329943
B7: Akseptasi Pensiun | C7: =Simulasi!I7 -> 4140000 | D7: fx=C3*C5 | E7: sisa | G7: 4 | H7: =H6-I7 -> 4.8846044e+08 | I7: =K7-J7 -> 1655072.3 | J7: =IF(G7<=$C$9,H6*$C$25/12,H6*$C$35/12) -> 4039368.7 | K7: =IFERROR(IF(G7<=$C$8,IF(G7<=$C$9,$C$6,$C$36),0),0) -> 5694441 | O7: 4 | P7: =P6-Q7 -> 4.744365e+08 | Q7: =S7-R7 -> 1409632.3 | R7: =IF(O7<=$C$9,P6*$V$5/12,P6*$V$14/12) -> 4284808.7 | S7: =IFERROR(IF(O7<=$C$8,IF(O7<=$C$9,$C$6,$V$15),0),0) -> 5694441 | U7: Kalkulasi Angsuran Pensiun | AA7: 83 bulan | AB7: 3550000 | AC7: 321000000 | AF7: 4 | AG7: =$AH$1/12*AI6 -> 3725520 | AH7: =R7-AG7 -> 559288.63 | AI7: =AI6-Q7-AH7 -> 5.1220716e+08 | AJ7: =AJ6-AH7 -> 37770655
B8: Tenor | C8: =Simulasi!B11 -> 180 | E8: =VLOOKUP(C8,G4:H183,2,FALSE) -> -9.2666596e-08 | G8: 5 | H8: =H7-I8 -> 4.8679173e+08 | I8: =K8-J8 -> 1668712.8 | J8: =IF(G8<=$C$9,H7*$C$25/12,H7*$C$35/12) -> 4025728.2 | K8: =IFERROR(IF(G8<=$C$8,IF(G8<=$C$9,$C$6,$C$36),0),0) -> 5694441 | O8: 5 | P8: =P7-Q8 -> 4.7301418e+08 | Q8: =S8-R8 -> 1422325.5 | R8: =IF(O8<=$C$9,P7*$V$5/12,P7*$V$14/12) -> 4272115.5 | S8: =IFERROR(IF(O8<=$C$8,IF(O8<=$C$9,$C$6,$V$15),0),0) -> 5694441 | U8: Sisa OS Pensiun | V8: =VLOOKUP(C9,O4:P183,2,FALSE) -> 1.8556462e+08 | X8: 2694655.2 | AF8: 5 | AG8: =$AH$1/12*AI7 -> 3711254 | AH8: =R8-AG8 -> 560861.48 | AI8: =AI7-Q8-AH8 -> 5.1022397e+08 | AJ8: =AJ7-AH8 -> 37209793
B9: Aktif | C9: =Simulasi!C8 -> 120 | G9: 6 | H9: =H8-I9 -> 4.8510927e+08 | I9: =K9-J9 -> 1682465.8 | J9: =IF(G9<=$C$9,H8*$C$25/12,H8*$C$35/12) -> 4011975.2 | K9: =IFERROR(IF(G9<=$C$8,IF(G9<=$C$9,$C$6,$C$36),0),0) -> 5694441 | O9: 6 | P9: =P8-Q9 -> 4.7157904e+08 | Q9: =S9-R9 -> 1435133 | R9: =IF(O9<=$C$9,P8*$V$5/12,P8*$V$14/12) -> 4259308 | S9: =IFERROR(IF(O9<=$C$8,IF(O9<=$C$9,$C$6,$V$15),0),0) -> 5694441 | U9: Atribusi per bulan | V9: =C13/C8 -> 222212.59 | X9: =PV(V10/12,V11,-X8,0,0) -> 1.2536837e+08 | AF9: 6 | AG9: =$AH$1/12*AI8 -> 3696884.6 | AH9: =R9-AG9 -> 562423.39 | AI9: =AI8-Q9-AH9 -> 5.0822641e+08 | AJ9: =AJ8-AH9 -> 36647370
B10: Pensiun | C10: =C8-C9 -> 60 | D10: jk atrib | G10: 7 | H10: =H9-I10 -> 4.8341293e+08 | I10: =K10-J10 -> 1696332.1 | J10: =IF(G10<=$C$9,H9*$C$25/12,H9*$C$35/12) -> 3998108.9 | K10: =IFERROR(IF(G10<=$C$8,IF(G10<=$C$9,$C$6,$C$36),0),0) -> 5694441 | O10: 7 | P10: =P9-Q10 -> 4.7013099e+08 | Q10: =S10-R10 -> 1448055.8 | R10: =IF(O10<=$C$9,P9*$V$5/12,P9*$V$14/12) -> 4246385.2 | S10: =IFERROR(IF(O10<=$C$8,IF(O10<=$C$9,$C$6,$V$15),0),0) -> 5694441 | U10: Rate Awal | V10: =Simulasi!$B$13 -> 0.105 | AF10: 7 | AG10: =$AH$1/12*AI9 -> 3682411.1 | AH10: =R10-AG10 -> 563974.1 | AI10: =AI9-Q10-AH10 -> 5.0621438e+08 | AJ10: =AJ9-AH10 -> 36083396
B11: rate aktif | C11: =Simulasi!B12+IF($D$13>0,0.001,0) -> 0.0935 | D11: ini udah oke, di NOS di plus 0,001 utk aktif | G11: 8 | H11: =H10-I11 -> 4.8170262e+08 | I11: =K11-J11 -> 1710312.7 | J11: =IF(G11<=$C$9,H10*$C$25/12,H10*$C$35/12) -> 3984128.3 | K11: =IFERROR(IF(G11<=$C$8,IF(G11<=$C$9,$C$6,$C$36),0),0) -> 5694441 | O11: 8 | P11: =P10-Q11 -> 4.6866989e+08 | Q11: =S11-R11 -> 1461095 | R11: =IF(O11<=$C$9,P10*$V$5/12,P10*$V$14/12) -> 4233346 | S11: =IFERROR(IF(O11<=$C$8,IF(O11<=$C$9,$C$6,$V$15),0),0) -> 5694441 | U11: Periode pensiun | V11: =C10 -> 60 | AF11: 8 | AG11: =$AH$1/12*AI10 -> 3667832.7 | AH11: =R11-AG11 -> 565513.31 | AI11: =AI10-Q11-AH11 -> 5.0418778e+08 | AJ11: =AJ10-AH11 -> 35517882
B12: rate pensiun | C12: =Simulasi!B13+IF($D$13>0,0.01,0) -> 0.115 | D12: ini udah oke, di NOS di plus 0,01 utk pensiun | G12: 9 | H12: =H11-I12 -> 4.7997821e+08 | I12: =K12-J12 -> 1724408.6 | J12: =IF(G12<=$C$9,H11*$C$25/12,H11*$C$35/12) -> 3970032.4 | K12: =IFERROR(IF(G12<=$C$8,IF(G12<=$C$9,$C$6,$C$36),0),0) -> 5694441 | O12: 9 | P12: =P11-Q12 -> 4.6719564e+08 | Q12: =S12-R12 -> 1474251.6 | R12: =IF(O12<=$C$9,P11*$V$5/12,P11*$V$14/12) -> 4220189.4 | S12: =IFERROR(IF(O12<=$C$8,IF(O12<=$C$9,$C$6,$V$15),0),0) -> 5694441 | U12: Angsuran | V12: =V10/12*V8 -> 1623690.5 | AF12: 9 | AG12: =$AH$1/12*AI11 -> 3653148.7 | AH12: =R12-AG12 -> 567040.73 | AI12: =AI11-Q12-AH12 -> 5.0214648e+08 | AJ12: =AJ11-AH12 -> 34950842
B13: Nominal Atribusi | C13: =IF(Simulasi!$C$14="2",Simulasi!B21,0) -> 39998267 | D13: =C13/C8 -> 222212.59 | G13: 10 | H13: =H12-I13 -> 4.7823959e+08 | I13: =K13-J13 -> 1738620.6 | J13: =IF(G13<=$C$9,H12*$C$25/12,H12*$C$35/12) -> 3955820.4 | K13: =IFERROR(IF(G13<=$C$8,IF(G13<=$C$9,$C$6,$C$36),0),0) -> 5694441 | O13: 10 | P13: =P12-Q13 -> 4.6570811e+08 | Q13: =S13-R13 -> 1487526.7 | R13: =IF(O13<=$C$9,P12*$V$5/12,P12*$V$14/12) -> 4206914.3 | S13: =IFERROR(IF(O13<=$C$8,IF(O13<=$C$9,$C$6,$V$15),0),0) -> 5694441 | U13: Final | V13: =V9+V12 -> 1845903 | AF13: 10 | AG13: =$AH$1/12*AI12 -> 3638358.3 | AH13: =R13-AG13 -> 568556.08 | AI13: =AI12-Q13-AH13 -> 5.000904e+08 | AJ13: =AJ12-AH13 -> 34382286
B14: Plafon Pengajuan | C14: =Simulasi!B10 -> 480000000 | G14: 11 | H14: =H13-I14 -> 4.7648664e+08 | I14: =K14-J14 -> 1752949.7 | J14: =IF(G14<=$C$9,H13*$C$25/12,H13*$C$35/12) -> 3941491.3 | K14: =IFERROR(IF(G14<=$C$8,IF(G14<=$C$9,$C$6,$C$36),0),0) -> 5694441 | O14: 11 | P14: =P13-Q14 -> 4.6420719e+08 | Q14: =S14-R14 -> 1500921.3 | R14: =IF(O14<=$C$9,P13*$V$5/12,P13*$V$14/12) -> 4193519.7 | S14: =IFERROR(IF(O14<=$C$8,IF(O14<=$C$9,$C$6,$V$15),0),0) -> 5694441 | U14: Rate Atrib | V14: =V13/V8*12+IF($D$13>0,0,0) -> 0.11936993 | AF14: 11 | AG14: =$AH$1/12*AI13 -> 3623460.7 | AH14: =R14-AG14 -> 570059.06 | AI14: =AI13-Q14-AH14 -> 4.9801942e+08 | AJ14: =AJ13-AH14 -> 33812227
A15: 1. | B15: SKEMA NO ATRIB Plafon MaksImal dihitung dengan menghitung plafon maksimal saat pensiun dan plafond maksimal saat aktif secara bersamaan | G15: 12 | H15: =H14-I15 -> 4.7471924e+08 | I15: =K15-J15 -> 1767396.9 | J15: =IF(G15<=$C$9,H14*$C$25/12,H14*$C$35/12) -> 3927044.1 | K15: =IFERROR(IF(G15<=$C$8,IF(G15<=$C$9,$C$6,$C$36),0),0) -> 5694441 | O15: 12 | P15: =P14-Q15 -> 4.6269276e+08 | Q15: =S15-R15 -> 1514436.5 | R15: =IF(O15<=$C$9,P14*$V$5/12,P14*$V$14/12) -> 4180004.5 | S15: =IFERROR(IF(O15<=$C$8,IF(O15<=$C$9,$C$6,$V$15),0),0) -> 5694441 | U15: Angsuran Final Pen | V15: =PMT(V14/12,V11,-V8,0,0) -> 4121876.7 | AF15: 12 | AG15: =$AH$1/12*AI14 -> 3608455.2 | AH15: =R15-AG15 -> 571549.37 | AI15: =AI14-Q15-AH15 -> 4.9593343e+08 | AJ15: =AJ14-AH15 -> 33240677
G16: 13 | H16: =H15-I16 -> 4.7293728e+08 | I16: =K16-J16 -> 1781963.2 | J16: =IF(G16<=$C$9,H15*$C$25/12,H15*$C$35/12) -> 3912477.8 | K16: =IFERROR(IF(G16<=$C$8,IF(G16<=$C$9,$C$6,$C$36),0),0) -> 5694441 | O16: 13 | P16: =P15-Q16 -> 4.6116468e+08 | Q16: =S16-R16 -> 1528073.4 | R16: =IF(O16<=$C$9,P15*$V$5/12,P15*$V$14/12) -> 4166367.6 | S16: =IFERROR(IF(O16<=$C$8,IF(O16<=$C$9,$C$6,$V$15),0),0) -> 5694441 | AF16: 13 | AG16: =$AH$1/12*AI15 -> 3593340.9 | AH16: =R16-AG16 -> 573026.71 | AI16: =AI15-Q16-AH16 -> 4.9383233e+08 | AJ16: =AJ15-AH16 -> 32667651
B17: Plafon Maksimal Pensiun | C17: =-PV(C12/12,C10,C7-D13, ,0) -> 1.7814111e+08 | D17: fx=-PV(C12/12;C10;C7;;0) | G17: 14 | H17: =H16-I17 -> 4.7114063e+08 | I17: =K17-J17 -> 1796649.6 | J17: =IF(G17<=$C$9,H16*$C$25/12,H16*$C$35/12) -> 3897791.4 | K17: =IFERROR(IF(G17<=$C$8,IF(G17<=$C$9,$C$6,$C$36),0),0) -> 5694441 | O17: 14 | P17: =P16-Q17 -> 4.5962285e+08 | Q17: =S17-R17 -> 1541833.1 | R17: =IF(O17<=$C$9,P16*$V$5/12,P16*$V$14/12) -> 4152607.9 | S17: =IFERROR(IF(O17<=$C$8,IF(O17<=$C$9,$C$6,$V$15),0),0) -> 5694441 | U17: Cek sisa OS | V17: =VLOOKUP(C8,O4:P183,2,FALSE) -> -7.962808e-08 | AF17: 14 | AG17: =$AH$1/12*AI16 -> 3578117.2 | AH17: =R17-AG17 -> 574490.76 | AI17: =AI16-Q17-AH17 -> 4.9171601e+08 | AJ17: =AJ16-AH17 -> 32093160
B18: Plafon Aktif | C18: =(ROUNDDOWN(-PV(C11/12,C9,C6-D13,C17,0)/10^6, )*10^6) -> 495000000 | D18: fx=ROUNDDOWN(-PV(C11/12;C9;C6;C17;0)/10^6;)*10^6 | G18: 15 | H18: =H17-I18 -> 4.6932917e+08 | I18: =K18-J18 -> 1811457 | J18: =IF(G18<=$C$9,H17*$C$25/12,H17*$C$35/12) -> 3882984 | K18: =IFERROR(IF(G18<=$C$8,IF(G18<=$C$9,$C$6,$C$36),0),0) -> 5694441 | O18: 15 | P18: =P17-Q18 -> 4.5806713e+08 | Q18: =S18-R18 -> 1555716.7 | R18: =IF(O18<=$C$9,P17*$V$5/12,P17*$V$14/12) -> 4138724.3 | S18: =IFERROR(IF(O18<=$C$8,IF(O18<=$C$9,$C$6,$V$15),0),0) -> 5694441 | AF18: 15 | AG18: =$AH$1/12*AI17 -> 3562783.1 | AH18: =R18-AG18 -> 575941.21 | AI18: =AI17-Q18-AH18 -> 4.8958435e+08 | AJ18: =AJ17-AH18 -> 31517219
G19: 16 | H19: =H18-I19 -> 4.6750279e+08 | I19: =K19-J19 -> 1826386.4 | J19: =IF(G19<=$C$9,H18*$C$25/12,H18*$C$35/12) -> 3868054.6 | K19: =IFERROR(IF(G19<=$C$8,IF(G19<=$C$9,$C$6,$C$36),0),0) -> 5694441 | O19: 16 | P19: =P18-Q19 -> 4.5649741e+08 | Q19: =S19-R19 -> 1569725.3 | R19: =IF(O19<=$C$9,P18*$V$5/12,P18*$V$14/12) -> 4124715.7 | S19: =IFERROR(IF(O19<=$C$8,IF(O19<=$C$9,$C$6,$V$15),0),0) -> 5694441 | AF19: 16 | AG19: =$AH$1/12*AI18 -> 3547337.9 | AH19: =R19-AG19 -> 577377.76 | AI19: =AI18-Q19-AH19 -> 4.8743725e+08 | AJ19: =AJ18-AH19 -> 30939841
A20: 2 | B20: Mencari Rate Atribusi Aktif | G20: 17 | H20: =H19-I20 -> 4.6566135e+08 | I20: =K20-J20 -> 1841438.9 | J20: =IF(G20<=$C$9,H19*$C$25/12,H19*$C$35/12) -> 3853002.1 | K20: =IFERROR(IF(G20<=$C$8,IF(G20<=$C$9,$C$6,$C$36),0),0) -> 5694441 | O20: 17 | P20: =P19-Q20 -> 4.5491355e+08 | Q20: =S20-R20 -> 1583860.1 | R20: =IF(O20<=$C$9,P19*$V$5/12,P19*$V$14/12) -> 4110580.9 | S20: =IFERROR(IF(O20<=$C$8,IF(O20<=$C$9,$C$6,$V$15),0),0) -> 5694441 | U20: Cfm | AF20: 17 | AG20: =$AH$1/12*AI19 -> 3531780.9 | AH20: =R20-AG20 -> 578800.07 | AI20: =AI19-Q20-AH20 -> 4.8527459e+08 | AJ20: =AJ19-AH20 -> 30361041
B21: Perhitungan dengan menggunakan margin + biaya atrib per bulan | G21: 18 | H21: =H20-I21 -> 4.6380473e+08 | I21: =K21-J21 -> 1856615.4 | J21: =IF(G21<=$C$9,H20*$C$25/12,H20*$C$35/12) -> 3837825.6 | K21: =IFERROR(IF(G21<=$C$8,IF(G21<=$C$9,$C$6,$C$36),0),0) -> 5694441 | O21: 18 | P21: =P20-Q21 -> 4.5331543e+08 | Q21: =S21-R21 -> 1598122.1 | R21: =IF(O21<=$C$9,P20*$V$5/12,P20*$V$14/12) -> 4096318.9 | S21: =IFERROR(IF(O21<=$C$8,IF(O21<=$C$9,$C$6,$V$15),0),0) -> 5694441 | U21: Penambahan atr aktif | V21: =1% -> 0.01 | AF21: 18 | AG21: =$AH$1/12*AI20 -> 3516111.1 | AH21: =R21-AG21 -> 580207.82 | AI21: =AI20-Q21-AH21 -> 4.8309626e+08 | AJ21: =AJ20-AH21 -> 29780833
B22: Rate Margin | C22: =(C11)/12*C18 -> 3856875 | D22: fx=C11/12*C18 | G22: 19 | H22: =H21-I22 -> 4.6193282e+08 | I22: =K22-J22 -> 1871917 | J22: =IF(G22<=$C$9,H21*$C$25/12,H21*$C$35/12) -> 3822524 | K22: =IFERROR(IF(G22<=$C$8,IF(G22<=$C$9,$C$6,$C$36),0),0) -> 5694441 | O22: 19 | P22: =P21-Q22 -> 4.5170291e+08 | Q22: =S22-R22 -> 1612512.6 | R22: =IF(O22<=$C$9,P21*$V$5/12,P21*$V$14/12) -> 4081928.4 | S22: =IFERROR(IF(O22<=$C$8,IF(O22<=$C$9,$C$6,$V$15),0),0) -> 5694441 | U22: penambahan atr pensiun | V22: 0 | AF22: 19 | AG22: =$AH$1/12*AI21 -> 3500327.7 | AH22: =R22-AG22 -> 581600.69 | AI22: =AI21-Q22-AH22 -> 4.8090215e+08 | AJ22: =AJ21-AH22 -> 29199232
B23: Atribusi per Bulan | C23: =C13/C8 -> 222212.59 | D23: fx=C13/C8 | G23: 20 | H23: =H22-I23 -> 4.6004547e+08 | I23: =K23-J23 -> 1887344.7 | J23: =IF(G23<=$C$9,H22*$C$25/12,H22*$C$35/12) -> 3807096.3 | K23: =IFERROR(IF(G23<=$C$8,IF(G23<=$C$9,$C$6,$C$36),0),0) -> 5694441 | O23: 20 | P23: =P22-Q23 -> 4.5007588e+08 | Q23: =S23-R23 -> 1627032.6 | R23: =IF(O23<=$C$9,P22*$V$5/12,P22*$V$14/12) -> 4067408.4 | S23: =IFERROR(IF(O23<=$C$8,IF(O23<=$C$9,$C$6,$V$15),0),0) -> 5694441 | AF23: 20 | AG23: =$AH$1/12*AI22 -> 3484430 | AH23: =R23-AG23 -> 582978.33 | AI23: =AI22-Q23-AH23 -> 4.7869213e+08 | AJ23: =AJ22-AH23 -> 28616254
B24: Margin + Atribusi | C24: =C22+C23 -> 4079087.6 | D24: fx=C22+C23 | G24: 21 | H24: =H23-I24 -> 4.5814257e+08 | I24: =K24-J24 -> 1902899.6 | J24: =IF(G24<=$C$9,H23*$C$25/12,H23*$C$35/12) -> 3791541.4 | K24: =IFERROR(IF(G24<=$C$8,IF(G24<=$C$9,$C$6,$C$36),0),0) -> 5694441 | O24: 21 | P24: =P23-Q24 -> 4.484342e+08 | Q24: =S24-R24 -> 1641683.4 | R24: =IF(O24<=$C$9,P23*$V$5/12,P23*$V$14/12) -> 4052757.6 | S24: =IFERROR(IF(O24<=$C$8,IF(O24<=$C$9,$C$6,$V$15),0),0) -> 5694441 | AF24: 21 | AG24: =$AH$1/12*AI23 -> 3468417.2 | AH24: =R24-AG24 -> 584340.42 | AI24: =AI23-Q24-AH24 -> 4.7646611e+08 | AJ24: =AJ23-AH24 -> 28031913
B25: Rate Atrib Aktif | C25: =ROUNDUP(C24/C18*12,4) -> 0.0989 | D25: fx=ROUNDUP(C24/C18*12;4) | G25: 22 | H25: =H24-I25 -> 4.5622399e+08 | I25: =K25-J25 -> 1918582.6 | J25: =IF(G25<=$C$9,H24*$C$25/12,H24*$C$35/12) -> 3775858.4 | K25: =IFERROR(IF(G25<=$C$8,IF(G25<=$C$9,$C$6,$C$36),0),0) -> 5694441 | O25: 22 | P25: =P24-Q25 -> 4.4677773e+08 | Q25: =S25-R25 -> 1656466.1 | R25: =IF(O25<=$C$9,P24*$V$5/12,P24*$V$14/12) -> 4037974.9 | S25: =IFERROR(IF(O25<=$C$8,IF(O25<=$C$9,$C$6,$V$15),0),0) -> 5694441 | AF25: 22 | AG25: =$AH$1/12*AI24 -> 3452288.3 | AH25: =R25-AG25 -> 585686.6 | AI25: =AI24-Q25-AH25 -> 4.7422396e+08 | AJ25: =AJ24-AH25 -> 27446227
G26: 23 | H26: =H25-I26 -> 4.542896e+08 | I26: =K26-J26 -> 1934394.9 | J26: =IF(G26<=$C$9,H25*$C$25/12,H25*$C$35/12) -> 3760046.1 | K26: =IFERROR(IF(G26<=$C$8,IF(G26<=$C$9,$C$6,$C$36),0),0) -> 5694441 | O26: 23 | P26: =P25-Q26 -> 4.4510635e+08 | Q26: =S26-R26 -> 1671382 | R26: =IF(O26<=$C$9,P25*$V$5/12,P25*$V$14/12) -> 4023059 | S26: =IFERROR(IF(O26<=$C$8,IF(O26<=$C$9,$C$6,$V$15),0),0) -> 5694441 | AF26: 23 | AG26: =$AH$1/12*AI25 -> 3436042.5 | AH26: =R26-AG26 -> 587016.54 | AI26: =AI25-Q26-AH26 -> 4.7196556e+08 | AJ26: =AJ25-AH26 -> 26859210
A27: 3 | B27: Buat jadwal angsuran terlebih dulu untuk mengetahui OS saat memasuki pensiun --> | G27: 24 | H27: =H26-I27 -> 4.5233926e+08 | I27: =K27-J27 -> 1950337.6 | J27: =IF(G27<=$C$9,H26*$C$25/12,H26*$C$35/12) -> 3744103.4 | K27: =IFERROR(IF(G27<=$C$8,IF(G27<=$C$9,$C$6,$C$36),0),0) -> 5694441 | O27: 24 | P27: =P26-Q27 -> 4.4341992e+08 | Q27: =S27-R27 -> 1686432.1 | R27: =IF(O27<=$C$9,P26*$V$5/12,P26*$V$14/12) -> 4008008.9 | S27: =IFERROR(IF(O27<=$C$8,IF(O27<=$C$9,$C$6,$V$15),0),0) -> 5694441 | AF27: 24 | AG27: =$AH$1/12*AI26 -> 3419679 | AH27: =R27-AG27 -> 588329.88 | AI27: =AI26-Q27-AH27 -> 4.696908e+08 | AJ27: =AJ26-AH27 -> 26270880
B28: Sisa OS saat pensiun | C28: =VLOOKUP(C9,G:H,2,FALSE) -> 1.6628891e+08 | D28: fx=H57 | G28: 25 | H28: =H27-I28 -> 4.5037285e+08 | I28: =K28-J28 -> 1966411.6 | J28: =IF(G28<=$C$9,H27*$C$25/12,H27*$C$35/12) -> 3728029.4 | K28: =IFERROR(IF(G28<=$C$8,IF(G28<=$C$9,$C$6,$C$36),0),0) -> 5694441 | O28: 25 | P28: =P27-Q28 -> 4.417183e+08 | Q28: =S28-R28 -> 1701617.8 | R28: =IF(O28<=$C$9,P27*$V$5/12,P27*$V$14/12) -> 3992823.2 | S28: =IFERROR(IF(O28<=$C$8,IF(O28<=$C$9,$C$6,$V$15),0),0) -> 5694441 | AF28: 25 | AG28: =$AH$1/12*AI27 -> 3403197 | AH28: =R28-AG28 -> 589626.25 | AI28: =AI27-Q28-AH28 -> 4.6739955e+08 | AJ28: =AJ27-AH28 -> 25681254
G29: 26 | H29: =H28-I29 -> 4.4839023e+08 | I29: =K29-J29 -> 1982618.1 | J29: =IF(G29<=$C$9,H28*$C$25/12,H28*$C$35/12) -> 3711822.9 | K29: =IFERROR(IF(G29<=$C$8,IF(G29<=$C$9,$C$6,$C$36),0),0) -> 5694441 | O29: 26 | P29: =P28-Q29 -> 4.4000136e+08 | Q29: =S29-R29 -> 1716940.2 | R29: =IF(O29<=$C$9,P28*$V$5/12,P28*$V$14/12) -> 3977500.8 | S29: =IFERROR(IF(O29<=$C$8,IF(O29<=$C$9,$C$6,$V$15),0),0) -> 5694441 | AF29: 26 | AG29: =$AH$1/12*AI28 -> 3386595.5 | AH29: =R29-AG29 -> 590905.31 | AI29: =AI28-Q29-AH29 -> 4.6509171e+08 | AJ29: =AJ28-AH29 -> 25090349
A30: 4 | B30: Mencari Rate Atribusi Pensiun | G30: 27 | H30: =H29-I30 -> 4.4639127e+08 | I30: =K30-J30 -> 1998958.2 | J30: =IF(G30<=$C$9,H29*$C$25/12,H29*$C$35/12) -> 3695482.8 | K30: =IFERROR(IF(G30<=$C$8,IF(G30<=$C$9,$C$6,$C$36),0),0) -> 5694441 | O30: 27 | P30: =P29-Q30 -> 4.3826896e+08 | Q30: =S30-R30 -> 1732400.5 | R30: =IF(O30<=$C$9,P29*$V$5/12,P29*$V$14/12) -> 3962040.5 | S30: =IFERROR(IF(O30<=$C$8,IF(O30<=$C$9,$C$6,$V$15),0),0) -> 5694441 | AF30: 27 | AG30: =$AH$1/12*AI29 -> 3369873.8 | AH30: =R30-AG30 -> 592166.69 | AI30: =AI29-Q30-AH30 -> 4.6276714e+08 | AJ30: =AJ29-AH30 -> 24498182
B31: Perhitungan dengan menggunakan margin dan atribusi per bulan | G31: 28 | H31: =H30-I31 -> 4.4437584e+08 | I31: =K31-J31 -> 2015433 | J31: =IF(G31<=$C$9,H30*$C$25/12,H30*$C$35/12) -> 3679008 | K31: =IFERROR(IF(G31<=$C$8,IF(G31<=$C$9,$C$6,$C$36),0),0) -> 5694441 | O31: 28 | P31: =P30-Q31 -> 4.3652096e+08 | Q31: =S31-R31 -> 1748000.1 | R31: =IF(O31<=$C$9,P30*$V$5/12,P30*$V$14/12) -> 3946440.9 | S31: =IFERROR(IF(O31<=$C$8,IF(O31<=$C$9,$C$6,$V$15),0),0) -> 5694441 | AF31: 28 | AG31: =$AH$1/12*AI30 -> 3353030.9 | AH31: =R31-AG31 -> 593410.01 | AI31: =AI30-Q31-AH31 -> 4.6042573e+08 | AJ31: =AJ30-AH31 -> 23904772
B32: Rate Margin 10,5% | C32: =(C12)/12*C28 -> 1593602.1 | D32: fx=C12/12*C28 | G32: 29 | H32: =H31-I32 -> 4.4234379e+08 | I32: =K32-J32 -> 2032043.5 | J32: =IF(G32<=$C$9,H31*$C$25/12,H31*$C$35/12) -> 3662397.5 | K32: =IFERROR(IF(G32<=$C$8,IF(G32<=$C$9,$C$6,$C$36),0),0) -> 5694441 | O32: 29 | P32: =P31-Q32 -> 4.3475722e+08 | Q32: =S32-R32 -> 1763740.2 | R32: =IF(O32<=$C$9,P31*$V$5/12,P31*$V$14/12) -> 3930700.8 | S32: =IFERROR(IF(O32<=$C$8,IF(O32<=$C$9,$C$6,$V$15),0),0) -> 5694441 | AF32: 29 | AG32: =$AH$1/12*AI31 -> 3336065.9 | AH32: =R32-AG32 -> 594634.9 | AI32: =AI31-Q32-AH32 -> 4.5806736e+08 | AJ32: =AJ31-AH32 -> 23310137
B33: Atribusi per Bulan | C33: =C13/C8 -> 222212.59 | D33: fx=C13/C8 | G33: 30 | H33: =H32-I33 -> 4.40295e+08 | I33: =K33-J33 -> 2048790.9 | J33: =IF(G33<=$C$9,H32*$C$25/12,H32*$C$35/12) -> 3645650.1 | K33: =IFERROR(IF(G33<=$C$8,IF(G33<=$C$9,$C$6,$C$36),0),0) -> 5694441 | O33: 30 | P33: =P32-Q33 -> 4.329776e+08 | Q33: =S33-R33 -> 1779622 | R33: =IF(O33<=$C$9,P32*$V$5/12,P32*$V$14/12) -> 3914819 | S33: =IFERROR(IF(O33<=$C$8,IF(O33<=$C$9,$C$6,$V$15),0),0) -> 5694441 | AF33: 30 | AG33: =$AH$1/12*AI32 -> 3318978 | AH33: =R33-AG33 -> 595840.98 | AI33: =AI32-Q33-AH33 -> 4.5569189e+08 | AJ33: =AJ32-AH33 -> 22714296
B34: Margin + Atribusi | C34: =C32+C33 -> 1815814.7 | D34: fx=C32+C33 | G34: 31 | H34: =H33-I34 -> 4.3822933e+08 | I34: =K34-J34 -> 2065676.4 | J34: =IF(G34<=$C$9,H33*$C$25/12,H33*$C$35/12) -> 3628764.6 | K34: =IFERROR(IF(G34<=$C$8,IF(G34<=$C$9,$C$6,$C$36),0),0) -> 5694441 | O34: 31 | P34: =P33-Q34 -> 4.3118195e+08 | Q34: =S34-R34 -> 1795646.8 | R34: =IF(O34<=$C$9,P33*$V$5/12,P33*$V$14/12) -> 3898794.2 | S34: =IFERROR(IF(O34<=$C$8,IF(O34<=$C$9,$C$6,$V$15),0),0) -> 5694441 | AF34: 31 | AG34: =$AH$1/12*AI33 -> 3301766.4 | AH34: =R34-AG34 -> 597027.86 | AI34: =AI33-Q34-AH34 -> 4.5329922e+08 | AJ34: =AJ33-AH34 -> 22117268
B35: Rate Atribusi Pensiun | C35: =ROUNDUP(C34/C28*12,4) -> 0.1311 | D35: fx=ROUNDUP(C34/C28*12;4) | G35: 32 | H35: =H34-I35 -> 4.3614662e+08 | I35: =K35-J35 -> 2082701 | J35: =IF(G35<=$C$9,H34*$C$25/12,H34*$C$35/12) -> 3611740 | K35: =IFERROR(IF(G35<=$C$8,IF(G35<=$C$9,$C$6,$C$36),0),0) -> 5694441 | O35: 32 | P35: =P34-Q35 -> 4.2937013e+08 | Q35: =S35-R35 -> 1811815.9 | R35: =IF(O35<=$C$9,P34*$V$5/12,P34*$V$14/12) -> 3882625.1 | S35: =IFERROR(IF(O35<=$C$8,IF(O35<=$C$9,$C$6,$V$15),0),0) -> 5694441 | AF35: 32 | AG35: =$AH$1/12*AI34 -> 3284430 | AH35: =R35-AG35 -> 598195.15 | AI35: =AI34-Q35-AH35 -> 4.5088921e+08 | AJ35: =AJ34-AH35 -> 21519073
B36: Angsuran Pensiun | C36: =PMT(C35/12,C10,-C28,0,0) -> 3792954.1 | D36: fx=PMT(C35/12;C10;-C28;0;0) | G36: 33 | H36: =H35-I36 -> 4.3404676e+08 | I36: =K36-J36 -> 2099865.9 | J36: =IF(G36<=$C$9,H35*$C$25/12,H35*$C$35/12) -> 3594575.1 | K36: =IFERROR(IF(G36<=$C$8,IF(G36<=$C$9,$C$6,$C$36),0),0) -> 5694441 | O36: 33 | P36: =P35-Q36 -> 4.27542e+08 | Q36: =S36-R36 -> 1828130.6 | R36: =IF(O36<=$C$9,P35*$V$5/12,P35*$V$14/12) -> 3866310.4 | S36: =IFERROR(IF(O36<=$C$8,IF(O36<=$C$9,$C$6,$V$15),0),0) -> 5694441 | AF36: 33 | AG36: =$AH$1/12*AI35 -> 3266968 | AH36: =R36-AG36 -> 599342.46 | AI36: =AI35-Q36-AH36 -> 4.4846173e+08 | AJ36: =AJ35-AH36 -> 20919731
C37: **angsuran pensiun melebihi 90% akseptasi Manfaat Pensiun, sehingga harus mengihitung ulang plafond aktif dan pensiun untuk skenario atribusi | G37: 34 | H37: =H36-I37 -> 4.3192959e+08 | I37: =K37-J37 -> 2117172.3 | J37: =IF(G37<=$C$9,H36*$C$25/12,H36*$C$35/12) -> 3577268.7 | K37: =IFERROR(IF(G37<=$C$8,IF(G37<=$C$9,$C$6,$C$36),0),0) -> 5694441 | O37: 34 | P37: =P36-Q37 -> 4.2569741e+08 | Q37: =S37-R37 -> 1844592.2 | R37: =IF(O37<=$C$9,P36*$V$5/12,P36*$V$14/12) -> 3849848.8 | S37: =IFERROR(IF(O37<=$C$8,IF(O37<=$C$9,$C$6,$V$15),0),0) -> 5694441 | AF37: 34 | AG37: =$AH$1/12*AI36 -> 3249379.4 | AH37: =R37-AG37 -> 600469.38 | AI37: =AI36-Q37-AH37 -> 4.4601667e+08 | AJ37: =AJ36-AH37 -> 20319261
G38: 35 | H38: =H37-I38 -> 4.2979497e+08 | I38: =K38-J38 -> 2134621.3 | J38: =IF(G38<=$C$9,H37*$C$25/12,H37*$C$35/12) -> 3559819.7 | K38: =IFERROR(IF(G38<=$C$8,IF(G38<=$C$9,$C$6,$C$36),0),0) -> 5694441 | O38: 35 | P38: =P37-Q38 -> 4.2383621e+08 | Q38: =S38-R38 -> 1861202 | R38: =IF(O38<=$C$9,P37*$V$5/12,P37*$V$14/12) -> 3833239 | S38: =IFERROR(IF(O38<=$C$8,IF(O38<=$C$9,$C$6,$V$15),0),0) -> 5694441 | AF38: 35 | AG38: =$AH$1/12*AI37 -> 3231663.5 | AH38: =R38-AG38 -> 601575.52 | AI38: =AI37-Q38-AH38 -> 4.4355389e+08 | AJ38: =AJ37-AH38 -> 19717686
A39: 5 | B39: SKEMA ATRIB Menghitung ulang menggunakan rate atribusi aktif dan pensiun pada langkah (2) dan (4) kemudian mencari plafond maksimal aktif dan pensiun menggunakan skenario Atribusi | G39: 36 | H39: =H38-I39 -> 4.2764275e+08 | I39: =K39-J39 -> 2152214.2 | J39: =IF(G39<=$C$9,H38*$C$25/12,H38*$C$35/12) -> 3542226.8 | K39: =IFERROR(IF(G39<=$C$8,IF(G39<=$C$9,$C$6,$C$36),0),0) -> 5694441 | O39: 36 | P39: =P38-Q39 -> 4.2195825e+08 | Q39: =S39-R39 -> 1877961.4 | R39: =IF(O39<=$C$9,P38*$V$5/12,P38*$V$14/12) -> 3816479.6 | S39: =IFERROR(IF(O39<=$C$8,IF(O39<=$C$9,$C$6,$V$15),0),0) -> 5694441 | AF39: 36 | AG39: =$AH$1/12*AI38 -> 3213819.1 | AH39: =R39-AG39 -> 602660.45 | AI39: =AI38-Q39-AH39 -> 4.4107327e+08 | AJ39: =AJ38-AH39 -> 19115025
G40: 37 | H40: =H39-I40 -> 4.254728e+08 | I40: =K40-J40 -> 2169952 | J40: =IF(G40<=$C$9,H39*$C$25/12,H39*$C$35/12) -> 3524489 | K40: =IFERROR(IF(G40<=$C$8,IF(G40<=$C$9,$C$6,$C$36),0),0) -> 5694441 | O40: 37 | P40: =P39-Q40 -> 4.2006338e+08 | Q40: =S40-R40 -> 1894871.7 | R40: =IF(O40<=$C$9,P39*$V$5/12,P39*$V$14/12) -> 3799569.3 | S40: =IFERROR(IF(O40<=$C$8,IF(O40<=$C$9,$C$6,$V$15),0),0) -> 5694441 | AF40: 37 | AG40: =$AH$1/12*AI39 -> 3195845.5 | AH40: =R40-AG40 -> 603723.76 | AI40: =AI39-Q40-AH40 -> 4.3857468e+08 | AJ40: =AJ39-AH40 -> 18511302
...

Sheet Rincian ke Nsb
B2: ATRIBUSI | H2: ATRIBUSI
B4: PRA PENSIUN DEKADE BERKAH | H4: PRA PENSIUN TRI BERKAH
B6: Nama Nasabah | C6: : | D6: =Akseptasi!C2 -> SITI HAFSAH | H6: Nama Nasabah | I6: : | J6: =Akseptasi!C2 -> SITI HAFSAH
B7: Plafond | C7: : | D7: =Simulasi!B10 -> 480000000 | H7: Plafond | I7: : | J7: =Simulasi!B10 -> 480000000
B8: Jangka Waktu | C8: : | D8: =Simulasi!B11 -> 180 | H8: Jangka Waktu | I8: : | J8: =Simulasi!B11 -> 180
B10: Angsuran saat Aktif PNS | C10: : | D10: =Simulasi!B32 -> 5694441 | E10: ='Jadwal Angsuran Dekade Berkah'!G3 -> 120 | F10: Bulan | H10: Angsuran saat Aktif PNS | I10: : | J10: =Simulasi!B32 -> 5694441 | K10: ='Jadwal Angsuran TriBerkah (Blok'!G3 -> 120 | L10: Bulan
B11: Angsuran saat Pensiun | C11: : | D11: =Simulasi!B33 -> 4121876.7 | E11: ='Jadwal Angsuran Dekade Berkah'!G4 -> 60 | F11: Bulan | H11: Angsuran saat Pensiun | I11: : | J11: =Simulasi!B33 -> 4121876.7 | K11: ='Jadwal Angsuran TriBerkah (Blok'!G4 -> 60 | L11: Bulan
B13: Biaya | H13: Biaya
B14: Administrasi (1%) | C14: : | D14: =1%*D7 -> 4800000 | H14: Administrasi (1%) | I14: : | J14: =1%*J7 -> 4800000
B15: Asuransi | C15: : | D15: 0 | H15: Asuransi | I15: : | J15: 0
B16: Materai | C16: : | D16: 100000 | H16: Materai | I16: : | J16: 100000
B18: Blokir Angsuran | H18: Blokir Angsuran
B19: Blokir 1x Angs Masa Aktif | C19: : | D19: =D10 -> 5694441 | H19: Blokir Angs Aktif + 2x Pensiun | I19: : | J19: =Simulasi!B37 -> blokir sesuai MP
B20: Blokir 2x Angs Masa Pensiun | C20: : | D20: =2*D11 -> 8243753.4
B22: Buka Blokir Yang Lama | C22: : | D22: =[1]Akseptasi!C22 -> 0
B24: Pelunasan Yang Lama | C24: : | D24: =[1]Akseptasi!C23 -> 0
B26: Terima Bersih | C26: : | D26: =D7-D14-D16-D19-D20-D24+D22 -> 4.6116181e+08 | H26: Terima Bersih | I26: : | J26: =J7-J14-J16-J19-J20-J24+J22 -> #VALUE!
B30: Syarat Dokumen Pembiayaan Pra Pen DEKADE BERKAH 10 Tahun (Mrbh atau MMQ) | H30: Syarat Dokumen Pembiayaan Pra Pen DEKADE BERKAH 10 Tahun (Mrbh atau MMQ) | O30: : | P30: YA
B31: Fotocopy KTP Suami dan Istri | H31: Fotocopy KTP Suami dan Istri | O31: : | P31: 27627574
B32: Fotocopy Kartu Keluarga | H32: Fotocopy Kartu Keluarga | O32: : | P32: 0
B33: Fotocopy Akte Nikah | H33: Fotocopy Akte Nikah | O33: : | P33: 0
B34: Fotocopy NPWP | H34: Fotocopy NPWP
B35: Asli SK PNS | H35: Asli SK PNS
B36: Asli SK Golongan terakhir | H36: Asli SK Golongan terakhir
B37: Fotocopy Rek Pensiun BSI | H37: Fotocopy Rek Pensiun BSI
B38: Amprah Gaji & Amprah Tunjangan 3 Bulan Terakhir (Stempel TTD) | H38: Amprah Gaji & Amprah Tunjangan 3 Bulan Terakhir (Stempel TTD)
B39: Rekening Koran atau Print Buku Tabungan Gaji 3 Bulan Terakhir | H39: Rekening Koran atau Print Buku Tabungan Gaji 3 Bulan Terakhir
B40: Fotocopy Surat Tanah/Rumah atas nama Nasabah/Pasangan (Jika Top Up atau Take Over) | H40: Fotocopy Surat Tanah/Rumah atas nama Nasabah/Pasangan (Jika Top Up atau Take Over)

Sheet Jadwal Angsuran Dekade Berkah
B1: Data Pembiayaan
B2: Produk | C2: : | D2: =Simulasi!B3 -> Prapen 10 Tahun | E2: Jangka waktu | F2: : | G2: =Simulasi!B11 -> 180 | H2: Price Aktif | I2: : | J2: =Simulasi!B34 -> 0.10805531
B3: Angsuran Aktif | C3: : | D3: =Simulasi!B32 -> 5694441 | E3: Tenor Aktif | F3: : | G3: ='Rumus Plafond + Atrib PP10 (2)'!C9 -> 120 | H3: Price Pensiun | I3: : | J3: =Simulasi!B35 -> 0.11936993
B4: Angsuran Pensiun | C4: : | D4: =Simulasi!B33 -> 4121876.7 | E4: Tenor Pensiun | F4: : | G4: ='Rumus Plafond + Atrib PP10 (2)'!C10 -> 60
C5: = | D5: INPUT
A6: Akad MMQ | O6: Akad Murabahah
B7: Harga/NilaiObjekAkad | C7: : | D7: 350000000 | E7: 1
B8: HishshahBANK | C8: : | D8: ='Rumus Plafond + Atrib PP10 (2)'!P3 -> 480000000 | E8: =D8/D7 -> 1.3714286
B9: HishshahNASABAH | C9: : | D9: =D7-D8 -> -130000000 | E9: =D9/D7 -> -0.37142857
B10: NisbahAwalBANK | C10: : | D10: =AVERAGE(E16:E195) -> 0.46263774
B11: NisbahAwalNASABAH | C11: : | D11: =AVERAGE(F16:F195) -> 0.53736226
B12: JangkaWaktu | C12: : | D12: =Simulasi!B11&" bulan" -> 180 bulan
R14: *untuk keperluan upload jadwal angsuran
A15: Ke- | B15: Tanggal | C15: Outstanding (Rp) | D15: Biaya Sewa/Ujrah Per Bulan (Rp) | E15: Nisbah Bank(%) | F15: Nisbah Nasabah (%) | G15: BagiHasil Bank (Rp) | H15: BagiHasil Nasabah (Rp) | I15: Hishshah Bank(%) | J15: Hishshah Nasabah (%) | K15: Biaya Sewa/ Ujrah Per Bulan(Rp) | O15: Angsuran ke | P15: Tanggal | Q15: Total Angsuran | R15: Margin | S15: Pokok | T15: Sisa OS
A16: ='Rumus Plafond + Atrib PP10 (2)'!O4 -> 1 | B16: =DATE(YEAR(Simulasi!B5),MONTH(Simulasi!B5)+1,1) -> 46327 | C16: =IFERROR('Rumus Plafond + Atrib PP10 (2)'!P4,"") -> 4.7862777e+08 | D16: =IFERROR('Rumus Plafond + Atrib PP10 (2)'!R4,"") -> 4322212.6 | E16: =IFERROR(G16/K16,"") -> 0.75902316 | F16: =IFERROR(H16/K16,"") -> 0.24097684 | G16: =IFERROR('Rumus Plafond + Atrib PP10 (2)'!R4,"") -> 4322212.6 | H16: =IFERROR('Rumus Plafond + Atrib PP10 (2)'!Q4,"") -> 1372228.4 | I16: =IFERROR(C16/$D$7,"") -> 1.3675079 | J16: =IFERROR(($D$7-C16)/$D$7,"") -> -0.36750792 | K16: =IFERROR('Rumus Plafond + Atrib PP10 (2)'!S4,"") -> 5694441 | O16: =A16 -> 1 | P16: =B16 -> 46327 | Q16: =K16 -> 5694441 | R16: =G16 -> 4322212.6 | S16: =H16 -> 1372228.4 | T16: =C16 -> 4.7862777e+08
A17: ='Rumus Plafond + Atrib PP10 (2)'!O5 -> 2 | B17: =IF(A17<=Simulasi!$B$11,DATE(YEAR(B16),MONTH(B16)+1,1),"") -> 46357 | C17: =IF(A17<=Simulasi!$B$11,'Rumus Plafond + Atrib PP10 (2)'!P5,"") -> 4.7724319e+08 | D17: =IFERROR('Rumus Plafond + Atrib PP10 (2)'!R5,"") -> 4309856.2 | E17: =IFERROR(G17/K17,"") -> 0.75685326 | F17: =IFERROR(H17/K17,"") -> 0.24314674 | G17: =IFERROR('Rumus Plafond + Atrib PP10 (2)'!R5,"") -> 4309856.2 | H17: =IFERROR('Rumus Plafond + Atrib PP10 (2)'!Q5,"") -> 1384584.8 | I17: =IFERROR(C17/$D$7,"") -> 1.363552 | J17: =IFERROR(($D$7-C17)/$D$7,"") -> -0.36355196 | K17: =IFERROR('Rumus Plafond + Atrib PP10 (2)'!S5,"") -> 5694441 | O17: =A17 -> 2 | P17: =B17 -> 46357 | Q17: =K17 -> 5694441 | R17: =G17 -> 4309856.2 | S17: =H17 -> 1384584.8 | T17: =C17 -> 4.7724319e+08
A18: ='Rumus Plafond + Atrib PP10 (2)'!O6 -> 3 | B18: =IF(A18<=Simulasi!$B$11,DATE(YEAR(B17),MONTH(B17)+1,1),"") -> 46388 | C18: =IF(A18<=Simulasi!$B$11,'Rumus Plafond + Atrib PP10 (2)'!P6,"") -> 4.7584613e+08 | D18: =IFERROR('Rumus Plafond + Atrib PP10 (2)'!R6,"") -> 4297388.6 | E18: =IFERROR(G18/K18,"") -> 0.75466381 | F18: =IFERROR(H18/K18,"") -> 0.24533619 | G18: =IFERROR('Rumus Plafond + Atrib PP10 (2)'!R6,"") -> 4297388.6 | H18: =IFERROR('Rumus Plafond + Atrib PP10 (2)'!Q6,"") -> 1397052.4 | I18: =IFERROR(C18/$D$7,"") -> 1.3595604 | J18: =IFERROR(($D$7-C18)/$D$7,"") -> -0.35956038 | K18: =IFERROR('Rumus Plafond + Atrib PP10 (2)'!S6,"") -> 5694441 | O18: =A18 -> 3 | P18: =B18 -> 46388 | Q18: =K18 -> 5694441 | R18: =G18 -> 4297388.6 | S18: =H18 -> 1397052.4 | T18: =C18 -> 4.7584613e+08
A19: ='Rumus Plafond + Atrib PP10 (2)'!O7 -> 4 | B19: =IF(A19<=Simulasi!$B$11,DATE(YEAR(B18),MONTH(B18)+1,1),"") -> 46419 | C19: =IF(A19<=Simulasi!$B$11,'Rumus Plafond + Atrib PP10 (2)'!P7,"") -> 4.744365e+08 | D19: =IFERROR('Rumus Plafond + Atrib PP10 (2)'!R7,"") -> 4284808.7 | E19: =IFERROR(G19/K19,"") -> 0.75245466 | F19: =IFERROR(H19/K19,"") -> 0.24754534 | G19: =IFERROR('Rumus Plafond + Atrib PP10 (2)'!R7,"") -> 4284808.7 | H19: =IFERROR('Rumus Plafond + Atrib PP10 (2)'!Q7,"") -> 1409632.3 | I19: =IFERROR(C19/$D$7,"") -> 1.3555329 | J19: =IFERROR(($D$7-C19)/$D$7,"") -> -0.35553286 | K19: =IFERROR('Rumus Plafond + Atrib PP10 (2)'!S7,"") -> 5694441 | O19: =A19 -> 4 | P19: =B19 -> 46419 | Q19: =K19 -> 5694441 | R19: =G19 -> 4284808.7 | S19: =H19 -> 1409632.3 | T19: =C19 -> 4.744365e+08
A20: ='Rumus Plafond + Atrib PP10 (2)'!O8 -> 5 | B20: =IF(A20<=Simulasi!$B$11,DATE(YEAR(B19),MONTH(B19)+1,1),"") -> 46447 | C20: =IF(A20<=Simulasi!$B$11,'Rumus Plafond + Atrib PP10 (2)'!P8,"") -> 4.7301418e+08 | D20: =IFERROR('Rumus Plafond + Atrib PP10 (2)'!R8,"") -> 4272115.5 | E20: =IFERROR(G20/K20,"") -> 0.75022561 | F20: =IFERROR(H20/K20,"") -> 0.24977439 | G20: =IFERROR('Rumus Plafond + Atrib PP10 (2)'!R8,"") -> 4272115.5 | H20: =IFERROR('Rumus Plafond + Atrib PP10 (2)'!Q8,"") -> 1422325.5 | I20: =IFERROR(C20/$D$7,"") -> 1.3514691 | J20: =IFERROR(($D$7-C20)/$D$7,"") -> -0.35146908 | K20: =IFERROR('Rumus Plafond + Atrib PP10 (2)'!S8,"") -> 5694441 | O20: =A20 -> 5 | P20: =B20 -> 46447 | Q20: =K20 -> 5694441 | R20: =G20 -> 4272115.5 | S20: =H20 -> 1422325.5 | T20: =C20 -> 4.7301418e+08
A21: ='Rumus Plafond + Atrib PP10 (2)'!O9 -> 6 | B21: =IF(A21<=Simulasi!$B$11,DATE(YEAR(B20),MONTH(B20)+1,1),"") -> 46478 | C21: =IF(A21<=Simulasi!$B$11,'Rumus Plafond + Atrib PP10 (2)'!P9,"") -> 4.7157904e+08 | D21: =IFERROR('Rumus Plafond + Atrib PP10 (2)'!R9,"") -> 4259308 | E21: =IFERROR(G21/K21,"") -> 0.74797649 | F21: =IFERROR(H21/K21,"") -> 0.25202351 | G21: =IFERROR('Rumus Plafond + Atrib PP10 (2)'!R9,"") -> 4259308 | H21: =IFERROR('Rumus Plafond + Atrib PP10 (2)'!Q9,"") -> 1435133 | I21: =IFERROR(C21/$D$7,"") -> 1.3473687 | J21: =IFERROR(($D$7-C21)/$D$7,"") -> -0.3473687 | K21: =IFERROR('Rumus Plafond + Atrib PP10 (2)'!S9,"") -> 5694441 | O21: =A21 -> 6 | P21: =B21 -> 46478 | Q21: =K21 -> 5694441 | R21: =G21 -> 4259308 | S21: =H21 -> 1435133 | T21: =C21 -> 4.7157904e+08
A22: ='Rumus Plafond + Atrib PP10 (2)'!O10 -> 7 | B22: =IF(A22<=Simulasi!$B$11,DATE(YEAR(B21),MONTH(B21)+1,1),"") -> 46508 | C22: =IF(A22<=Simulasi!$B$11,'Rumus Plafond + Atrib PP10 (2)'!P10,"") -> 4.7013099e+08 | D22: =IFERROR('Rumus Plafond + Atrib PP10 (2)'!R10,"") -> 4246385.2 | E22: =IFERROR(G22/K22,"") -> 0.74570711 | F22: =IFERROR(H22/K22,"") -> 0.25429289 | G22: =IFERROR('Rumus Plafond + Atrib PP10 (2)'!R10,"") -> 4246385.2 | H22: =IFERROR('Rumus Plafond + Atrib PP10 (2)'!Q10,"") -> 1448055.8 | I22: =IFERROR(C22/$D$7,"") -> 1.3432314 | J22: =IFERROR(($D$7-C22)/$D$7,"") -> -0.34323139 | K22: =IFERROR('Rumus Plafond + Atrib PP10 (2)'!S10,"") -> 5694441 | O22: =A22 -> 7 | P22: =B22 -> 46508 | Q22: =K22 -> 5694441 | R22: =G22 -> 4246385.2 | S22: =H22 -> 1448055.8 | T22: =C22 -> 4.7013099e+08
A23: ='Rumus Plafond + Atrib PP10 (2)'!O11 -> 8 | B23: =IF(A23<=Simulasi!$B$11,DATE(YEAR(B22),MONTH(B22)+1,1),"") -> 46539 | C23: =IF(A23<=Simulasi!$B$11,'Rumus Plafond + Atrib PP10 (2)'!P11,"") -> 4.6866989e+08 | D23: =IFERROR('Rumus Plafond + Atrib PP10 (2)'!R11,"") -> 4233346 | E23: =IFERROR(G23/K23,"") -> 0.74341731 | F23: =IFERROR(H23/K23,"") -> 0.25658269 | G23: =IFERROR('Rumus Plafond + Atrib PP10 (2)'!R11,"") -> 4233346 | H23: =IFERROR('Rumus Plafond + Atrib PP10 (2)'!Q11,"") -> 1461095 | I23: =IFERROR(C23/$D$7,"") -> 1.3390568 | J23: =IFERROR(($D$7-C23)/$D$7,"") -> -0.33905684 | K23: =IFERROR('Rumus Plafond + Atrib PP10 (2)'!S11,"") -> 5694441 | O23: =A23 -> 8 | P23: =B23 -> 46539 | Q23: =K23 -> 5694441 | R23: =G23 -> 4233346 | S23: =H23 -> 1461095 | T23: =C23 -> 4.6866989e+08
A24: ='Rumus Plafond + Atrib PP10 (2)'!O12 -> 9 | B24: =IF(A24<=Simulasi!$B$11,DATE(YEAR(B23),MONTH(B23)+1,1),"") -> 46569 | C24: =IF(A24<=Simulasi!$B$11,'Rumus Plafond + Atrib PP10 (2)'!P12,"") -> 4.6719564e+08 | D24: =IFERROR('Rumus Plafond + Atrib PP10 (2)'!R12,"") -> 4220189.4 | E24: =IFERROR(G24/K24,"") -> 0.74110688 | F24: =IFERROR(H24/K24,"") -> 0.25889312 | G24: =IFERROR('Rumus Plafond + Atrib PP10 (2)'!R12,"") -> 4220189.4 | H24: =IFERROR('Rumus Plafond + Atrib PP10 (2)'!Q12,"") -> 1474251.6 | I24: =IFERROR(C24/$D$7,"") -> 1.3348447 | J24: =IFERROR(($D$7-C24)/$D$7,"") -> -0.33484469 | K24: =IFERROR('Rumus Plafond + Atrib PP10 (2)'!S12,"") -> 5694441 | O24: =A24 -> 9 | P24: =B24 -> 46569 | Q24: =K24 -> 5694441 | R24: =G24 -> 4220189.4 | S24: =H24 -> 1474251.6 | T24: =C24 -> 4.6719564e+08
A25: ='Rumus Plafond + Atrib PP10 (2)'!O13 -> 10 | B25: =IF(A25<=Simulasi!$B$11,DATE(YEAR(B24),MONTH(B24)+1,1),"") -> 46600 | C25: =IF(A25<=Simulasi!$B$11,'Rumus Plafond + Atrib PP10 (2)'!P13,"") -> 4.6570811e+08 | D25: =IFERROR('Rumus Plafond + Atrib PP10 (2)'!R13,"") -> 4206914.3 | E25: =IFERROR(G25/K25,"") -> 0.73877565 | F25: =IFERROR(H25/K25,"") -> 0.26122435 | G25: =IFERROR('Rumus Plafond + Atrib PP10 (2)'!R13,"") -> 4206914.3 | H25: =IFERROR('Rumus Plafond + Atrib PP10 (2)'!Q13,"") -> 1487526.7 | I25: =IFERROR(C25/$D$7,"") -> 1.3305946 | J25: =IFERROR(($D$7-C25)/$D$7,"") -> -0.33059461 | K25: =IFERROR('Rumus Plafond + Atrib PP10 (2)'!S13,"") -> 5694441 | O25: =A25 -> 10 | P25: =B25 -> 46600 | Q25: =K25 -> 5694441 | R25: =G25 -> 4206914.3 | S25: =H25 -> 1487526.7 | T25: =C25 -> 4.6570811e+08
A26: ='Rumus Plafond + Atrib PP10 (2)'!O14 -> 11 | B26: =IF(A26<=Simulasi!$B$11,DATE(YEAR(B25),MONTH(B25)+1,1),"") -> 46631 | C26: =IF(A26<=Simulasi!$B$11,'Rumus Plafond + Atrib PP10 (2)'!P14,"") -> 4.6420719e+08 | D26: =IFERROR('Rumus Plafond + Atrib PP10 (2)'!R14,"") -> 4193519.7 | E26: =IFERROR(G26/K26,"") -> 0.73642342 | F26: =IFERROR(H26/K26,"") -> 0.26357658 | G26: =IFERROR('Rumus Plafond + Atrib PP10 (2)'!R14,"") -> 4193519.7 | H26: =IFERROR('Rumus Plafond + Atrib PP10 (2)'!Q14,"") -> 1500921.3 | I26: =IFERROR(C26/$D$7,"") -> 1.3263063 | J26: =IFERROR(($D$7-C26)/$D$7,"") -> -0.32630627 | K26: =IFERROR('Rumus Plafond + Atrib PP10 (2)'!S14,"") -> 5694441 | O26: =A26 -> 11 | P26: =B26 -> 46631 | Q26: =K26 -> 5694441 | R26: =G26 -> 4193519.7 | S26: =H26 -> 1500921.3 | T26: =C26 -> 4.6420719e+08
A27: ='Rumus Plafond + Atrib PP10 (2)'!O15 -> 12 | B27: =IF(A27<=Simulasi!$B$11,DATE(YEAR(B26),MONTH(B26)+1,1),"") -> 46661 | C27: =IF(A27<=Simulasi!$B$11,'Rumus Plafond + Atrib PP10 (2)'!P15,"") -> 4.6269276e+08 | D27: =IFERROR('Rumus Plafond + Atrib PP10 (2)'!R15,"") -> 4180004.5 | E27: =IFERROR(G27/K27,"") -> 0.73405002 | F27: =IFERROR(H27/K27,"") -> 0.26594998 | G27: =IFERROR('Rumus Plafond + Atrib PP10 (2)'!R15,"") -> 4180004.5 | H27: =IFERROR('Rumus Plafond + Atrib PP10 (2)'!Q15,"") -> 1514436.5 | I27: =IFERROR(C27/$D$7,"") -> 1.3219793 | J27: =IFERROR(($D$7-C27)/$D$7,"") -> -0.3219793 | K27: =IFERROR('Rumus Plafond + Atrib PP10 (2)'!S15,"") -> 5694441 | O27: =A27 -> 12 | P27: =B27 -> 46661 | Q27: =K27 -> 5694441 | R27: =G27 -> 4180004.5 | S27: =H27 -> 1514436.5 | T27: =C27 -> 4.6269276e+08
A28: ='Rumus Plafond + Atrib PP10 (2)'!O16 -> 13 | B28: =IF(A28<=Simulasi!$B$11,DATE(YEAR(B27),MONTH(B27)+1,1),"") -> 46692 | C28: =IF(A28<=Simulasi!$B$11,'Rumus Plafond + Atrib PP10 (2)'!P16,"") -> 4.6116468e+08 | D28: =IFERROR('Rumus Plafond + Atrib PP10 (2)'!R16,"") -> 4166367.6 | E28: =IFERROR(G28/K28,"") -> 0.73165525 | F28: =IFERROR(H28/K28,"") -> 0.26834475 | G28: =IFERROR('Rumus Plafond + Atrib PP10 (2)'!R16,"") -> 4166367.6 | H28: =IFERROR('Rumus Plafond + Atrib PP10 (2)'!Q16,"") -> 1528073.4 | I28: =IFERROR(C28/$D$7,"") -> 1.3176134 | J28: =IFERROR(($D$7-C28)/$D$7,"") -> -0.31761338 | K28: =IFERROR('Rumus Plafond + Atrib PP10 (2)'!S16,"") -> 5694441 | O28: =A28 -> 13 | P28: =B28 -> 46692 | Q28: =K28 -> 5694441 | R28: =G28 -> 4166367.6 | S28: =H28 -> 1528073.4 | T28: =C28 -> 4.6116468e+08
... A195: ='Rumus Plafond + Atrib PP10 (2)'!O183 -> 180 | B195: =IF(A195<=Simulasi!$B$11,DATE(YEAR(B194),MONTH(B194)+1,1),"") -> 51775 | C195: =IF(A195<=Simulasi!$B$11,'Rumus Plafond + Atrib PP10 (2)'!P183,"") -> -7.962808e-08 | D195: =IFERROR('Rumus Plafond + Atrib PP10 (2)'!R183,"") -> 40598.492 | E195: =IFERROR(G195/K195,"") -> 0.0098495164 | F195: =IFERROR(H195/K195,"") -> 0.99015048 | G195: =IFERROR('Rumus Plafond + Atrib PP10 (2)'!R183,"") -> 40598.492 | H195: =IFERROR('Rumus Plafond + Atrib PP10 (2)'!Q183,"") -> 4081278.2 | I195: =IFERROR(C195/$D$7,"") -> -2.275088e-16 | J195: =IFERROR(($D$7-C195)/$D$7,"") -> 1 | K195: =IFERROR('Rumus Plafond + Atrib PP10 (2)'!S183,"") -> 4121876.7 | O195: =A195 -> 180 | P195: =B195 -> 51775 | Q195: =K195 -> 4121876.7 | R195: =G195 -> 40598.492 | S195: =H195 -> 4081278.2 | T195: =C195 -> -7.962808e-08

Sheet Jadwal Angsuran TriBerkah (Blok
B1: Data Pembiayaan
B2: Produk | C2: : | D2: =Simulasi!B3 -> Prapen 10 Tahun | E2: Jangka waktu | F2: : | G2: =Simulasi!B11 -> 180 | H2: Price Aktif | I2: : | J2: =Simulasi!B34 -> 0.10805531
B3: Angsuran Aktif | C3: : | D3: =Simulasi!B32 -> 5694441 | E3: Tenor Aktif | F3: : | G3: ='Rumus Plafond + Atrib PP10 (2)'!C9 -> 120 | H3: Price Pensiun | I3: : | J3: =Simulasi!B35 -> 0.11936993
B4: Angsuran Pensiun | C4: : | D4: =Simulasi!B33 -> 4121876.7 | E4: Tenor Pensiun | F4: : | G4: ='Rumus Plafond + Atrib PP10 (2)'!C10 -> 60
C5: = | D5: INPUT
A6: Akad MMQ
B7: Harga/NilaiObjekAkad | C7: : | D7: 350000000 | E7: 1
B8: HishshahBANK | C8: : | D8: ='Rumus Plafond + Atrib PP3'!P3 -> 178000000 | E8: =D8/D7 -> 0.50857143
B9: HishshahNASABAH | C9: : | D9: =D7-D8 -> 172000000 | E9: =D9/D7 -> 0.49142857
B10: NisbahAwalBANK | C10: : | D10: =AVERAGE(E16:E195) -> 0.75388634
B11: NisbahAwalNASABAH | C11: : | D11: =AVERAGE(F16:F195) -> 0.24611366
B12: JangkaWaktu | C12: : | D12: =Simulasi!B11&" bulan" -> 180 bulan
A15: Ke- | B15: Tanggal | C15: Outstanding (Rp) | D15: Biaya Sewa/Ujrah Per Bulan (Rp) | E15: Nisbah Bank(%) | F15: Nisbah Nasabah (%) | G15: BagiHasil Bank (Rp) | H15: BagiHasil Nasabah (Rp) | I15: Hishshah Bank(%) | J15: Hishshah Nasabah (%) | K15: Biaya Sewa/ Ujrah Per Bulan(Rp)
A16: ='Rumus Plafond + Atrib PP10 (2)'!O4 -> 1 | B16: =DATE(YEAR(Simulasi!B5),MONTH(Simulasi!B5)+1,1) -> 46327 | C16: ='Rumus Plafond + Atrib PP3'!P4 -> 177990000 | D16: =IFERROR('Rumus Plafond + Atrib PP3'!R4,"") -> 1594295.9 | E16: =IFERROR(G16/K16,"") -> 0.99376674 | F16: =IFERROR(H16/K16,"") -> 0.006233264 | G16: =IFERROR('Rumus Plafond + Atrib PP3'!R4,"") -> 1594295.9 | H16: =IFERROR('Rumus Plafond + Atrib PP3'!Q4,"") -> 10000 | I16: =IFERROR(C16/$D$7,"") -> 0.50854286 | J16: =IFERROR(($D$7-C16)/$D$7,"") -> 0.49145714 | K16: =IFERROR('Rumus Plafond + Atrib PP3'!S4,"") -> 1604295.9
A17: ='Rumus Plafond + Atrib PP10 (2)'!O5 -> 2 | B17: =IF(A17<=Simulasi!$B$11,DATE(YEAR(B16),MONTH(B16)+1,1),"") -> 46357 | C17: =IF(A17<=Simulasi!$B$11,'Rumus Plafond + Atrib PP3'!P5,"") -> 1.7797991e+08 | D17: =IFERROR('Rumus Plafond + Atrib PP3'!R5,"") -> 1594206.4 | E17: =IFERROR(G17/K17,"") -> 0.99371091 | F17: =IFERROR(H17/K17,"") -> 0.0062890936 | G17: =IFERROR('Rumus Plafond + Atrib PP3'!R5,"") -> 1594206.4 | H17: =IFERROR('Rumus Plafond + Atrib PP3'!Q5,"") -> 10089.567 | I17: =IFERROR(C17/$D$7,"") -> 0.50851403 | J17: =IFERROR(($D$7-C17)/$D$7,"") -> 0.49148597 | K17: =IFERROR('Rumus Plafond + Atrib PP3'!S5,"") -> 1604295.9
A18: ='Rumus Plafond + Atrib PP10 (2)'!O6 -> 3 | B18: =IF(A18<=Simulasi!$B$11,DATE(YEAR(B17),MONTH(B17)+1,1),"") -> 46388 | C18: =IF(A18<=Simulasi!$B$11,'Rumus Plafond + Atrib PP3'!P6,"") -> 1.7796973e+08 | D18: =IFERROR('Rumus Plafond + Atrib PP3'!R6,"") -> 1594116 | E18: =IFERROR(G18/K18,"") -> 0.99365458 | F18: =IFERROR(H18/K18,"") -> 0.0063454232 | G18: =IFERROR('Rumus Plafond + Atrib PP3'!R6,"") -> 1594116 | H18: =IFERROR('Rumus Plafond + Atrib PP3'!Q6,"") -> 10179.937 | I18: =IFERROR(C18/$D$7,"") -> 0.50848494 | J18: =IFERROR(($D$7-C18)/$D$7,"") -> 0.49151506 | K18: =IFERROR('Rumus Plafond + Atrib PP3'!S6,"") -> 1604295.9
A19: ='Rumus Plafond + Atrib PP10 (2)'!O7 -> 4 | B19: =IF(A19<=Simulasi!$B$11,DATE(YEAR(B18),MONTH(B18)+1,1),"") -> 46419 | C19: =IF(A19<=Simulasi!$B$11,'Rumus Plafond + Atrib PP3'!P7,"") -> 1.7795946e+08 | D19: =IFERROR('Rumus Plafond + Atrib PP3'!R7,"") -> 1594024.8 | E19: =IFERROR(G19/K19,"") -> 0.99359774 | F19: =IFERROR(H19/K19,"") -> 0.0064022574 | G19: =IFERROR('Rumus Plafond + Atrib PP3'!R7,"") -> 1594024.8 | H19: =IFERROR('Rumus Plafond + Atrib PP3'!Q7,"") -> 10271.115 | I19: =IFERROR(C19/$D$7,"") -> 0.5084556 | J19: =IFERROR(($D$7-C19)/$D$7,"") -> 0.4915444 | K19: =IFERROR('Rumus Plafond + Atrib PP3'!S7,"") -> 1604295.9
A20: ='Rumus Plafond + Atrib PP10 (2)'!O8 -> 5 | B20: =IF(A20<=Simulasi!$B$11,DATE(YEAR(B19),MONTH(B19)+1,1),"") -> 46447 | C20: =IF(A20<=Simulasi!$B$11,'Rumus Plafond + Atrib PP3'!P8,"") -> 1.779491e+08 | D20: =IFERROR('Rumus Plafond + Atrib PP3'!R8,"") -> 1593932.8 | E20: =IFERROR(G20/K20,"") -> 0.9935404 | F20: =IFERROR(H20/K20,"") -> 0.0064596006 | G20: =IFERROR('Rumus Plafond + Atrib PP3'!R8,"") -> 1593932.8 | H20: =IFERROR('Rumus Plafond + Atrib PP3'!Q8,"") -> 10363.111 | I20: =IFERROR(C20/$D$7,"") -> 0.50842599 | J20: =IFERROR(($D$7-C20)/$D$7,"") -> 0.49157401 | K20: =IFERROR('Rumus Plafond + Atrib PP3'!S8,"") -> 1604295.9
A21: ='Rumus Plafond + Atrib PP10 (2)'!O9 -> 6 | B21: =IF(A21<=Simulasi!$B$11,DATE(YEAR(B20),MONTH(B20)+1,1),"") -> 46478 | C21: =IF(A21<=Simulasi!$B$11,'Rumus Plafond + Atrib PP3'!P9,"") -> 1.7793864e+08 | D21: =IFERROR('Rumus Plafond + Atrib PP3'!R9,"") -> 1593840 | E21: =IFERROR(G21/K21,"") -> 0.99348254 | F21: =IFERROR(H21/K21,"") -> 0.0065174574 | G21: =IFERROR('Rumus Plafond + Atrib PP3'!R9,"") -> 1593840 | H21: =IFERROR('Rumus Plafond + Atrib PP3'!Q9,"") -> 10455.93 | I21: =IFERROR(C21/$D$7,"") -> 0.50839612 | J21: =IFERROR(($D$7-C21)/$D$7,"") -> 0.49160388 | K21: =IFERROR('Rumus Plafond + Atrib PP3'!S9,"") -> 1604295.9
A22: ='Rumus Plafond + Atrib PP10 (2)'!O10 -> 7 | B22: =IF(A22<=Simulasi!$B$11,DATE(YEAR(B21),MONTH(B21)+1,1),"") -> 46508 | C22: =IF(A22<=Simulasi!$B$11,'Rumus Plafond + Atrib PP3'!P10,"") -> 1.7792809e+08 | D22: =IFERROR('Rumus Plafond + Atrib PP3'!R10,"") -> 1593746.3 | E22: =IFERROR(G22/K22,"") -> 0.99342417 | F22: =IFERROR(H22/K22,"") -> 0.0065758324 | G22: =IFERROR('Rumus Plafond + Atrib PP3'!R10,"") -> 1593746.3 | H22: =IFERROR('Rumus Plafond + Atrib PP3'!Q10,"") -> 10549.581 | I22: =IFERROR(C22/$D$7,"") -> 0.50836597 | J22: =IFERROR(($D$7-C22)/$D$7,"") -> 0.49163403 | K22: =IFERROR('Rumus Plafond + Atrib PP3'!S10,"") -> 1604295.9
A23: ='Rumus Plafond + Atrib PP10 (2)'!O11 -> 8 | B23: =IF(A23<=Simulasi!$B$11,DATE(YEAR(B22),MONTH(B22)+1,1),"") -> 46539 | C23: =IF(A23<=Simulasi!$B$11,'Rumus Plafond + Atrib PP3'!P11,"") -> 1.7791745e+08 | D23: =IFERROR('Rumus Plafond + Atrib PP3'!R11,"") -> 1593651.9 | E23: =IFERROR(G23/K23,"") -> 0.99336527 | F23: =IFERROR(H23/K23,"") -> 0.0066347303 | G23: =IFERROR('Rumus Plafond + Atrib PP3'!R11,"") -> 1593651.9 | H23: =IFERROR('Rumus Plafond + Atrib PP3'!Q11,"") -> 10644.071 | I23: =IFERROR(C23/$D$7,"") -> 0.50833556 | J23: =IFERROR(($D$7-C23)/$D$7,"") -> 0.49166444 | K23: =IFERROR('Rumus Plafond + Atrib PP3'!S11,"") -> 1604295.9
A24: ='Rumus Plafond + Atrib PP10 (2)'!O12 -> 9 | B24: =IF(A24<=Simulasi!$B$11,DATE(YEAR(B23),MONTH(B23)+1,1),"") -> 46569 | C24: =IF(A24<=Simulasi!$B$11,'Rumus Plafond + Atrib PP3'!P12,"") -> 1.7790671e+08 | D24: =IFERROR('Rumus Plafond + Atrib PP3'!R12,"") -> 1593556.5 | E24: =IFERROR(G24/K24,"") -> 0.99330584 | F24: =IFERROR(H24/K24,"") -> 0.0066941557 | G24: =IFERROR('Rumus Plafond + Atrib PP3'!R12,"") -> 1593556.5 | H24: =IFERROR('Rumus Plafond + Atrib PP3'!Q12,"") -> 10739.407 | I24: =IFERROR(C24/$D$7,"") -> 0.50830488 | J24: =IFERROR(($D$7-C24)/$D$7,"") -> 0.49169512 | K24: =IFERROR('Rumus Plafond + Atrib PP3'!S12,"") -> 1604295.9
A25: ='Rumus Plafond + Atrib PP10 (2)'!O13 -> 10 | B25: =IF(A25<=Simulasi!$B$11,DATE(YEAR(B24),MONTH(B24)+1,1),"") -> 46600 | C25: =IF(A25<=Simulasi!$B$11,'Rumus Plafond + Atrib PP3'!P13,"") -> 1.7789587e+08 | D25: =IFERROR('Rumus Plafond + Atrib PP3'!R13,"") -> 1593460.3 | E25: =IFERROR(G25/K25,"") -> 0.99324589 | F25: =IFERROR(H25/K25,"") -> 0.0067541134 | G25: =IFERROR('Rumus Plafond + Atrib PP3'!R13,"") -> 1593460.3 | H25: =IFERROR('Rumus Plafond + Atrib PP3'!Q13,"") -> 10835.597 | I25: =IFERROR(C25/$D$7,"") -> 0.50827392 | J25: =IFERROR(($D$7-C25)/$D$7,"") -> 0.49172608 | K25: =IFERROR('Rumus Plafond + Atrib PP3'!S13,"") -> 1604295.9
A26: ='Rumus Plafond + Atrib PP10 (2)'!O14 -> 11 | B26: =IF(A26<=Simulasi!$B$11,DATE(YEAR(B25),MONTH(B25)+1,1),"") -> 46631 | C26: =IF(A26<=Simulasi!$B$11,'Rumus Plafond + Atrib PP3'!P14,"") -> 1.7788494e+08 | D26: =IFERROR('Rumus Plafond + Atrib PP3'!R14,"") -> 1593363.3 | E26: =IFERROR(G26/K26,"") -> 0.99318539 | F26: =IFERROR(H26/K26,"") -> 0.0068146081 | G26: =IFERROR('Rumus Plafond + Atrib PP3'!R14,"") -> 1593363.3 | H26: =IFERROR('Rumus Plafond + Atrib PP3'!Q14,"") -> 10932.648 | I26: =IFERROR(C26/$D$7,"") -> 0.50824268 | J26: =IFERROR(($D$7-C26)/$D$7,"") -> 0.49175732 | K26: =IFERROR('Rumus Plafond + Atrib PP3'!S14,"") -> 1604295.9
A27: ='Rumus Plafond + Atrib PP10 (2)'!O15 -> 12 | B27: =IF(A27<=Simulasi!$B$11,DATE(YEAR(B26),MONTH(B26)+1,1),"") -> 46661 | C27: =IF(A27<=Simulasi!$B$11,'Rumus Plafond + Atrib PP3'!P15,"") -> 1.7787391e+08 | D27: =IFERROR('Rumus Plafond + Atrib PP3'!R15,"") -> 1593265.4 | E27: =IFERROR(G27/K27,"") -> 0.99312436 | F27: =IFERROR(H27/K27,"") -> 0.0068756446 | G27: =IFERROR('Rumus Plafond + Atrib PP3'!R15,"") -> 1593265.4 | H27: =IFERROR('Rumus Plafond + Atrib PP3'!Q15,"") -> 11030.569 | I27: =IFERROR(C27/$D$7,"") -> 0.50821117 | J27: =IFERROR(($D$7-C27)/$D$7,"") -> 0.49178883 | K27: =IFERROR('Rumus Plafond + Atrib PP3'!S15,"") -> 1604295.9
A28: ='Rumus Plafond + Atrib PP10 (2)'!O16 -> 13 | B28: =IF(A28<=Simulasi!$B$11,DATE(YEAR(B27),MONTH(B27)+1,1),"") -> 46692 | C28: =IF(A28<=Simulasi!$B$11,'Rumus Plafond + Atrib PP3'!P16,"") -> 1.7786278e+08 | D28: =IFERROR('Rumus Plafond + Atrib PP3'!R16,"") -> 1593166.6 | E28: =IFERROR(G28/K28,"") -> 0.99306277 | F28: =IFERROR(H28/K28,"") -> 0.0069372278 | G28: =IFERROR('Rumus Plafond + Atrib PP3'!R16,"") -> 1593166.6 | H28: =IFERROR('Rumus Plafond + Atrib PP3'!Q16,"") -> 11129.366 | I28: =IFERROR(C28/$D$7,"") -> 0.50817937 | J28: =IFERROR(($D$7-C28)/$D$7,"") -> 0.49182063 | K28: =IFERROR('Rumus Plafond + Atrib PP3'!S16,"") -> 1604295.9
... A195: ='Rumus Plafond + Atrib PP10 (2)'!O183 -> 180 | B195: =IF(A195<=Simulasi!$B$11,DATE(YEAR(B194),MONTH(B194)+1,1),"") -> 51775 | C195: =IF(A195<=Simulasi!$B$11,'Rumus Plafond + Atrib PP3'!P183,"") -> 0 | D195: =IFERROR('Rumus Plafond + Atrib PP3'!R183,"") -> 47233.161 | E195: =IFERROR(G195/K195,"") -> 0.011540267 | F195: =IFERROR(H195/K195,"") -> 0.98845973 | G195: =IFERROR('Rumus Plafond + Atrib PP3'!R183,"") -> 47233.161 | H195: =IFERROR('Rumus Plafond + Atrib PP3'!Q183,"") -> 4045666.9 | I195: =IFERROR(C195/$D$7,"") -> 0 | J195: =IFERROR(($D$7-C195)/$D$7,"") -> 1 | K195: =IFERROR('Rumus Plafond + Atrib PP3'!S183,"") -> 4092900
A196: ='Rumus Plafond + Atrib PP3'!O184 -> 181 | B196: =IF(A196<=Simulasi!$B$11,DATE(YEAR(B195),MONTH(B195)+1,1),"") | C196: =IF(A196<=Simulasi!$B$11,'Rumus Plafond + Atrib PP3'!P184,"") | D196: =IFERROR('Rumus Plafond + Atrib PP3'!R184,"") -> 0 | E196: =IFERROR(G196/K196,"") | F196: =IFERROR(H196/K196,"") | G196: =IFERROR('Rumus Plafond + Atrib PP3'!R184,"") -> 0 | H196: =IFERROR('Rumus Plafond + Atrib PP3'!Q184,"") -> 0 | I196: =IFERROR(C196/$D$7,"") | J196: =IFERROR(($D$7-C196)/$D$7,"") | K196: =IFERROR('Rumus Plafond + Atrib PP3'!S184,"") -> 0
A197: ='Rumus Plafond + Atrib PP3'!O185 -> 182 | B197: =IF(A197<=Simulasi!$B$11,DATE(YEAR(B196),MONTH(B196)+1,1),"") | C197: =IF(A197<=Simulasi!$B$11,'Rumus Plafond + Atrib PP3'!P185,"") | D197: =IFERROR('Rumus Plafond + Atrib PP3'!R185,"") -> 0 | E197: =IFERROR(G197/K197,"") | F197: =IFERROR(H197/K197,"") | G197: =IFERROR('Rumus Plafond + Atrib PP3'!R185,"") -> 0 | H197: =IFERROR('Rumus Plafond + Atrib PP3'!Q185,"") -> 0 | I197: =IFERROR(C197/$D$7,"") | J197: =IFERROR(($D$7-C197)/$D$7,"") | K197: =IFERROR('Rumus Plafond + Atrib PP3'!S185,"") -> 0
A198: ='Rumus Plafond + Atrib PP3'!O186 -> 183 | B198: =IF(A198<=Simulasi!$B$11,DATE(YEAR(B197),MONTH(B197)+1,1),"") | C198: =IF(A198<=Simulasi!$B$11,'Rumus Plafond + Atrib PP3'!P186,"") | D198: =IFERROR('Rumus Plafond + Atrib PP3'!R186,"") -> 0 | E198: =IFERROR(G198/K198,"") | F198: =IFERROR(H198/K198,"") | G198: =IFERROR('Rumus Plafond + Atrib PP3'!R186,"") -> 0 | H198: =IFERROR('Rumus Plafond + Atrib PP3'!Q186,"") -> 0 | I198: =IFERROR(C198/$D$7,"") | J198: =IFERROR(($D$7-C198)/$D$7,"") | K198: =IFERROR('Rumus Plafond + Atrib PP3'!S186,"") -> 0
